<?xml version="1.0" ?>
<!-- =================================================================================== -->
<!-- |    This document was autogenerated by xacro from robot.urdf.xacro               | -->
<!-- |    EDITING THIS FILE BY HAND IS NOT RECOMMENDED                                 | -->
<!-- =================================================================================== -->
<robot name="robot">
  <!-- <xacro:include filename="robot_core.xacro" /> -->
  <include filename="color_macro.xacro"/>
  <include filename="inertia_macro.xacro"/>
  <!-- Define Common Colors to be used elsewhere -->
  <material name="black">
    <color rgba="0.0 0.0 0.0 1.0"/>
  </material>
  <material name="dark">
    <color rgba="0.3 0.3 0.3 1.0"/>
  </material>
  <material name="light_black">
    <color rgba="0.4 0.4 0.4 1.0"/>
  </material>
  <material name="blue">
    <color rgba="0.0 0.0 0.8 1.0"/>
  </material>
  <material name="green">
    <color rgba="0.0 0.8 0.0 1.0"/>
  </material>
  <material name="grey">
    <color rgba="0.5 0.5 0.5 1.0"/>
  </material>
  <material name="orange">
    <color rgba="1.0 0.4235 0.0392 1.0"/>
  </material>
  <material name="brown">
    <color rgba="0.8706 0.8118 0.7647 1.0"/>
  </material>
  <material name="red">
    <color rgba="0.8 0.0 0.0 1.0"/>
  </material>
  <material name="white">
    <color rgba="1.0 1.0 1.0 1.0"/>
  </material>
  <!-- Specify some standard inertial calculations https://en.wikipedia.org/wiki/List_of_moments_of_inertia -->
  <!-- These make use of xacro's mathematical functionality -->
  <!-- <xacro:arg name="is_simulation" default="true" /> -->
  <!-- Define a base links for the robot. base_link and base_footprint needed for Nav2 -->
  <link name="base_footprint"/>
  <joint name="base_joint" type="fixed">
    <parent link="base_footprint"/>
    <child link="base_link"/>
    <origin rpy="0 0 0" xyz="0 0 1.1"/>
  </joint>
  <link name="base_link"/>
  <!-- Define a chassis link for the robot -->
  <joint name="chassis_joint" type="fixed">
    <parent link="base_link"/>
    <child link="chassis"/>
    <!-- Place the chassis at half of chassis height above the base link -->
    <origin rpy="0 0 0" xyz="0 0 0.15"/>
  </joint>
  <link name="chassis">
    <visual>
      <origin xyz="0 0 0"/>
      <geometry>
        <box size="3 1.5 0.3"/>
      </geometry>
      <material name="grey"/>
    </visual>
    <collision>
      <origin xyz="0 0 0"/>
      <geometry>
        <box size="3 1.5 0.3"/>
      </geometry>
    </collision>
    <inertial>
      <origin rpy="0 0 0" xyz="0 0 0"/>
      <mass value="30.0"/>
      <inertia ixx="5.85" ixy="0.0" ixz="0.0" iyy="22.725" iyz="0.0" izz="28.125"/>
    </inertial>
  </link>
  <!-- Define joints to connect static links to the base link -->
  <joint name="FL_joint" type="fixed">
    <parent link="base_link"/>
    <child link="front_left"/>
    <origin rpy="0 0 0" xyz="1.2 0.6 0"/>
  </joint>
  <joint name="FR_joint" type="fixed">
    <parent link="base_link"/>
    <child link="front_right"/>
    <origin rpy="0 0 0" xyz="1.2 -0.6 0"/>
  </joint>
  <joint name="RL_joint" type="fixed">
    <parent link="base_link"/>
    <child link="rear_left"/>
    <origin rpy="0 0 0" xyz="-1.2 0.6 0"/>
  </joint>
  <joint name="RR_joint" type="fixed">
    <parent link="base_link"/>
    <child link="rear_right"/>
    <origin rpy="0 0 0" xyz="-1.2 -0.6 0"/>
  </joint>
  <!-- Define 4 static links which will be used to connect the wheel modules to the base link -->
  <link name="front_left">
    </link>
  <link name="front_right">
    </link>
  <link name="rear_left">
    </link>
  <link name="rear_right">
    </link>
  <!--
        Firstly create a link for the wheel module
        Then create a joint to connect the wheel module to the parent link
        Then create a link for wheel
        Then create a joint to connect the wheel to the wheel module
        -->
  <joint name="wheel_module_front_left_joint" type="fixed">
    <parent link="front_left"/>
    <child link="wheel_module_front_left"/>
    <origin rpy="0 0 0" xyz="0 0 -0.4"/>
    <!-- This origin is where child link is placed w.r.t parent link -->
  </joint>
  <!-- Define the wheel module link -->
  <link name="wheel_module_front_left">
    <visual>
      <origin xyz="0 0 0"/>
      <!-- This origin is w.r.t the wheel_module_${parent_name} link -->
      <geometry>
        <box size="0.2 0.15 0.8"/>
      </geometry>
      <material name="grey"/>
    </visual>
    <collision>
      <origin xyz="0 0 0"/>
      <!-- This origin is w.r.t the wheel_module_${parent_name} link -->
      <geometry>
        <box size="0.2 0.15 0.8"/>
      </geometry>
    </collision>
    <inertial>
      <origin rpy="0 0 0" xyz="0 0 0"/>
      <mass value="2.0"/>
      <inertia ixx="0.11041666666666668" ixy="0.0" ixz="0.0" iyy="0.11333333333333336" iyz="0.0" izz="0.010416666666666666"/>
    </inertial>
  </link>
  <joint name="wheel_front_left_joint" type="continuous">
    <parent link="wheel_module_front_left"/>
    <child link="wheel_front_left"/>
    <origin rpy="-1.5707963267948966 0 0" xyz="0 0.1 -0.4"/>
    <axis xyz="0 0 1"/>
  </joint>
  <link name="wheel_front_left">
    <visual>
      <geometry>
        <cylinder length="0.1" radius="0.3"/>
      </geometry>
      <material name="grey"/>
    </visual>
    <collision>
      <geometry>
        <cylinder length="0.1" radius="0.3"/>
      </geometry>
    </collision>
    <inertial>
      <origin rpy="0 0 0" xyz="0 0 0"/>
      <mass value="1.0"/>
      <inertia ixx="0.02333333333333333" ixy="0.0" ixz="0.0" iyy="0.02333333333333333" iyz="0.0" izz="0.045"/>
    </inertial>
  </link>
  <!--
        Firstly create a link for the wheel module
        Then create a joint to connect the wheel module to the parent link
        Then create a link for wheel
        Then create a joint to connect the wheel to the wheel module
        -->
  <joint name="wheel_module_front_right_joint" type="fixed">
    <parent link="front_right"/>
    <child link="wheel_module_front_right"/>
    <origin rpy="0 0 0" xyz="0 0 -0.4"/>
    <!-- This origin is where child link is placed w.r.t parent link -->
  </joint>
  <!-- Define the wheel module link -->
  <link name="wheel_module_front_right">
    <visual>
      <origin xyz="0 0 0"/>
      <!-- This origin is w.r.t the wheel_module_${parent_name} link -->
      <geometry>
        <box size="0.2 0.15 0.8"/>
      </geometry>
      <material name="grey"/>
    </visual>
    <collision>
      <origin xyz="0 0 0"/>
      <!-- This origin is w.r.t the wheel_module_${parent_name} link -->
      <geometry>
        <box size="0.2 0.15 0.8"/>
      </geometry>
    </collision>
    <inertial>
      <origin rpy="0 0 0" xyz="0 0 0"/>
      <mass value="2.0"/>
      <inertia ixx="0.11041666666666668" ixy="0.0" ixz="0.0" iyy="0.11333333333333336" iyz="0.0" izz="0.010416666666666666"/>
    </inertial>
  </link>
  <joint name="wheel_front_right_joint" type="continuous">
    <parent link="wheel_module_front_right"/>
    <child link="wheel_front_right"/>
    <origin rpy="1.5707963267948966 0 0" xyz="0 -0.1 -0.4"/>
    <axis xyz="0 0 1"/>
  </joint>
  <link name="wheel_front_right">
    <visual>
      <geometry>
        <cylinder length="0.1" radius="0.3"/>
      </geometry>
      <material name="grey"/>
    </visual>
    <collision>
      <geometry>
        <cylinder length="0.1" radius="0.3"/>
      </geometry>
    </collision>
    <inertial>
      <origin rpy="0 0 0" xyz="0 0 0"/>
      <mass value="1.0"/>
      <inertia ixx="0.02333333333333333" ixy="0.0" ixz="0.0" iyy="0.02333333333333333" iyz="0.0" izz="0.045"/>
    </inertial>
  </link>
  <!--
        Firstly create a link for the wheel module
        Then create a joint to connect the wheel module to the parent link
        Then create a link for wheel
        Then create a joint to connect the wheel to the wheel module
        -->
  <joint name="wheel_module_rear_left_joint" type="fixed">
    <parent link="rear_left"/>
    <child link="wheel_module_rear_left"/>
    <origin rpy="0 0 0" xyz="0 0 -0.4"/>
    <!-- This origin is where child link is placed w.r.t parent link -->
  </joint>
  <!-- Define the wheel module link -->
  <link name="wheel_module_rear_left">
    <visual>
      <origin xyz="0 0 0"/>
      <!-- This origin is w.r.t the wheel_module_${parent_name} link -->
      <geometry>
        <box size="0.2 0.15 0.8"/>
      </geometry>
      <material name="grey"/>
    </visual>
    <collision>
      <origin xyz="0 0 0"/>
      <!-- This origin is w.r.t the wheel_module_${parent_name} link -->
      <geometry>
        <box size="0.2 0.15 0.8"/>
      </geometry>
    </collision>
    <inertial>
      <origin rpy="0 0 0" xyz="0 0 0"/>
      <mass value="2.0"/>
      <inertia ixx="0.11041666666666668" ixy="0.0" ixz="0.0" iyy="0.11333333333333336" iyz="0.0" izz="0.010416666666666666"/>
    </inertial>
  </link>
  <joint name="wheel_rear_left_joint" type="continuous">
    <parent link="wheel_module_rear_left"/>
    <child link="wheel_rear_left"/>
    <origin rpy="-1.5707963267948966 0 0" xyz="0 0.1 -0.4"/>
    <axis xyz="0 0 1"/>
  </joint>
  <link name="wheel_rear_left">
    <visual>
      <geometry>
        <cylinder length="0.1" radius="0.3"/>
      </geometry>
      <material name="grey"/>
    </visual>
    <collision>
      <geometry>
        <cylinder length="0.1" radius="0.3"/>
      </geometry>
    </collision>
    <inertial>
      <origin rpy="0 0 0" xyz="0 0 0"/>
      <mass value="1.0"/>
      <inertia ixx="0.02333333333333333" ixy="0.0" ixz="0.0" iyy="0.02333333333333333" iyz="0.0" izz="0.045"/>
    </inertial>
  </link>
  <!--
        Firstly create a link for the wheel module
        Then create a joint to connect the wheel module to the parent link
        Then create a link for wheel
        Then create a joint to connect the wheel to the wheel module
        -->
  <joint name="wheel_module_rear_right_joint" type="fixed">
    <parent link="rear_right"/>
    <child link="wheel_module_rear_right"/>
    <origin rpy="0 0 0" xyz="0 0 -0.4"/>
    <!-- This origin is where child link is placed w.r.t parent link -->
  </joint>
  <!-- Define the wheel module link -->
  <link name="wheel_module_rear_right">
    <visual>
      <origin xyz="0 0 0"/>
      <!-- This origin is w.r.t the wheel_module_${parent_name} link -->
      <geometry>
        <box size="0.2 0.15 0.8"/>
      </geometry>
      <material name="grey"/>
    </visual>
    <collision>
      <origin xyz="0 0 0"/>
      <!-- This origin is w.r.t the wheel_module_${parent_name} link -->
      <geometry>
        <box size="0.2 0.15 0.8"/>
      </geometry>
    </collision>
    <inertial>
      <origin rpy="0 0 0" xyz="0 0 0"/>
      <mass value="2.0"/>
      <inertia ixx="0.11041666666666668" ixy="0.0" ixz="0.0" iyy="0.11333333333333336" iyz="0.0" izz="0.010416666666666666"/>
    </inertial>
  </link>
  <joint name="wheel_rear_right_joint" type="continuous">
    <parent link="wheel_module_rear_right"/>
    <child link="wheel_rear_right"/>
    <origin rpy="1.5707963267948966 0 0" xyz="0 -0.1 -0.4"/>
    <axis xyz="0 0 1"/>
  </joint>
  <link name="wheel_rear_right">
    <visual>
      <geometry>
        <cylinder length="0.1" radius="0.3"/>
      </geometry>
      <material name="grey"/>
    </visual>
    <collision>
      <geometry>
        <cylinder length="0.1" radius="0.3"/>
      </geometry>
    </collision>
    <inertial>
      <origin rpy="0 0 0" xyz="0 0 0"/>
      <mass value="1.0"/>
      <inertia ixx="0.02333333333333333" ixy="0.0" ixz="0.0" iyy="0.02333333333333333" iyz="0.0" izz="0.045"/>
    </inertial>
  </link>
  <!-- IMU temporarily placed 5cm above base link -->
  <joint name="imu_joint" type="fixed">
    <parent link="base_link"/>
    <child link="imu_link"/>
    <origin rpy="0 0 0" xyz="0.0 0.0 0.09999999999999999"/>
  </joint>
  <link name="imu_link"/>
  <!-- GPS link at base link -->
  <joint name="gps_joint" type="fixed">
    <parent link="base_link"/>
    <child link="gps_link"/>
    <origin rpy="0 0 0" xyz="0 0 0"/>
  </joint>
  <link name="gps_link"/>
  <!-- 2D Lidar placed in front center 20cm below chassis-->
  <joint name="scan_joint" type="fixed">
    <parent link="base_link"/>
    <child link="base_scan"/>
    <origin rpy="0 0 0" xyz="1.5 0 -0.2"/>
  </joint>
  <link name="base_scan">
    <visual>
      <origin rpy="0 0 0" xyz="0 0 0"/>
      <geometry>
        <mesh filename="package://turtlebot3_gazebo/models/turtlebot3_common/meshes/lds.dae" scale="0.001 0.001 0.001"/>
      </geometry>
      <material name="dark"/>
    </visual>
    <collision>
      <origin rpy="0 0 0" xyz="0.015 0 -0.0065"/>
      <geometry>
        <cylinder length="0.0315" radius="0.055"/>
      </geometry>
    </collision>
    <inertial>
      <mass value="0.114"/>
      <origin xyz="0 0 0"/>
      <inertia ixx="0.001" ixy="0.0" ixz="0.0" iyy="0.001" iyz="0.0" izz="0.001"/>
    </inertial>
  </link>
</robot>
