Here is the converted `robot.sdf` using the provided `robot.urdf` content and incorporating the sensor information from the given SDF example. 

```xml
<?xml version="1.0"?>
<sdf version="1.6">
  <model name="robot">
    <pose>0 0 0 0 0 0</pose>

    <!-- Define Common Colors -->
    <material name="black">
      <color rgba="0.0 0.0 0.0 1.0"/>
    </material>
    <material name="dark">
      <color rgba="0.3 0.3 0.3 1.0"/>
    </material>
    <material name="light_black">
      <color rgba="0.4 0.4 0.4 1.0"/>
    </material>
    <material name="blue">
      <color rgba="0.0 0.0 0.8 1.0"/>
    </material>
    <material name="green">
      <color rgba="0.0 0.8 0.0 1.0"/>
    </material>
    <material name="grey">
      <color rgba="0.5 0.5 0.5 1.0"/>
    </material>
    <material name="orange">
      <color rgba="1.0 0.4235 0.0392 1.0"/>
    </material>
    <material name="brown">
      <color rgba="0.8706 0.8118 0.7647 1.0"/>
    </material>
    <material name="red">
      <color rgba="0.8 0.0 0.0 1.0"/>
    </material>
    <material name="white">
      <color rgba="1.0 1.0 1.0 1.0"/>
    </material>

    <!-- Define Links and Joints -->
    <link name="base_footprint"/>

    <joint name="base_joint" type="fixed">
      <parent>base_footprint</parent>
      <child>base_link</child>
      <pose>0 0 1.1 0 0 0</pose>
    </joint>

    <link name="base_link"/>

    <joint name="chassis_joint" type="fixed">
      <parent>base_link</parent>
      <child>chassis</child>
      <pose>0 0 0.15 0 0 0</pose>
    </joint>

    <link name="chassis">
      <visual name="chassis_visual">
        <pose>0 0 0 0 0 0</pose>
        <geometry>
          <box>
            <size>3 1.5 0.3</size>
          </box>
        </geometry>
        <material>grey</material>
      </visual>
      <collision name="chassis_collision">
        <pose>0 0 0 0 0 0</pose>
        <geometry>
          <box>
            <size>3 1.5 0.3</size>
          </box>
        </geometry>
      </collision>
      <inertial>
        <pose>0 0 0 0 0 0</pose>
        <mass>30.0</mass>
        <inertia>
          <ixx>5.85</ixx>
          <ixy>0.0</ixy>
          <ixz>0.0</ixx>
          <iyy>22.725</iyy>
          <iyz>0.0</iyz>
          <izz>28.125</izz>
        </inertia>
      </inertial>
    </link>

    <!-- Front and Rear Link Joints -->
    <joint name="FL_joint" type="fixed">
      <parent>base_link</parent>
      <child>front_left</child>
      <pose>1.2 0.6 0 0 0 0</pose>
    </joint>
    <joint name="FR_joint" type="fixed">
      <parent>base_link</parent>
      <child>front_right</child>
      <pose>1.2 -0.6 0 0 0 0</pose>
    </joint>
    <joint name="RL_joint" type="fixed">
      <parent>base_link</parent>
      <child>rear_left</child>
      <pose>-1.2 0.6 0 0 0 0</pose>
    </joint>
    <joint name="RR_joint" type="fixed">
      <parent>base_link</parent>
      <child>rear_right</child>
      <pose>-1.2 -0.6 0 0 0 0</pose>
    </joint>

    <!-- Front and Rear Links -->
    <link name="front_left"/>
    <link name="front_right"/>
    <link name="rear_left"/>
    <link name="rear_right"/>

    <!-- Wheel Modules -->
    <joint name="wheel_module_front_left_joint" type="fixed">
      <parent>front_left</parent>
      <child>wheel_module_front_left</child>
      <pose>0 0 -0.4 0 0 0</pose>
    </joint>
    <link name="wheel_module_front_left">
      <visual name="wheel_module_front_left_visual">
        <pose>0 0 0 0 0 0</pose>
        <geometry>
          <box>
            <size>0.2 0.15 0.8</size>
          </box>
        </geometry>
        <material>grey</material>
      </visual>
      <collision name="wheel_module_front_left_collision">
        <pose>0 0 0 0 0 0</pose>
        <geometry>
          <box>
            <size>0.2 0.15 0.8</size>
          </box>
        </geometry>
      </collision>
      <inertial>
        <pose>0 0 0 0 0 0</pose>
        <mass>2.0</mass>
        <inertia>
          <ixx>0.11041666666666668</ixx>
          <ixy>0.0</ixy>
          <ixz>0.0</ixx>
          <iyy>0.11333333333333336</iyy>
          <iyz>0.0</iyz>
          <izz>0.010416666666666666</izz>
        </inertia>
      </inertial>
    </link>
    <joint name="wheel_front_left_joint" type="continuous">
      <parent>wheel_module_front_left</parent>
      <child>wheel_front_left</child>
      <pose>0 0.1 -0.4 -1.5707963267948966 0 0</pose>
      <axis>
        <xyz>0 0 1</xyz>
      </axis>
    </joint>
    <link name="wheel_front_left">
      <visual name="wheel_front_left_visual">
        <geometry>
          <cylinder>
            <radius>0.3</radius>
            <length>0.1</length>
          </cylinder>
        </geometry>
        <material>grey</material>
      </visual>
      <collision name="wheel_front_left_collision">
        <geometry>
          <cylinder>
            <radius>0.3</radius>
            <length>0.1</length>
          </cylinder>
        </geometry>
        <surface>
          <!-- This friction pamareter don't contain reliable data!! -->
          <friction>
            <ode>
              <mu>100000.0</mu>
              <mu2>100000.0</mu2>
              <fdir1>0 0 0</fdir1>
              <slip1>0.0</slip1>
              <slip2>0.0</slip2>
            </ode>
          </friction>
          <contact>
            <ode>
              <soft_cfm>0</soft_cfm>
              <soft_erp>0.2</soft_erp>
              <kp>1e+5</kp>
              <kd>1</kd>
              <max_vel>0.01</max_vel>
              <min_depth>0.001</min_depth>
            </ode>
          </contact>
        </surface>
      </collision>
      <inertial>
        <pose>0 0 0 0 0 0</pose>
        <mass>1.0</mass>
        <inertia>
          <ixx>0.02333333333333333</ixx>
          <ixy>0.0</ixy>
          <ixz>0.0</ixx>
          <iyy>0.02333333333333333</iyy>
          <iyz>0.0</iyz>
          <izz>0.045</izz>
        </inertia>
      </inertial>
    </link>

    <joint name="wheel_module_front_right_joint" type="fixed">
      <parent>front_right</parent>
      <child>wheel_module_front_right</child>
      <pose>0 0 -0.4 0 0 0</pose>
    </joint>
    <link name="wheel_module_front_right">
      <visual name="wheel_module_front_right_visual">
        <pose>0 0 0 0 0 0</pose>
        <geometry>
          <box>
            <size>0.2 0.15 0.8</size>
          </box>
        </geometry>
        <material>grey</material>
      </visual>
      <collision name="wheel_module_front_right_collision">
        <pose>0 0 0 0 0 0</pose>
        <geometry>
          <box>
            <size>0.2 0.15 0.8</size>
          </box>
        </geometry>
      </collision>
      <inertial>
        <pose>0 0 0 0 0 0</pose>
        <mass>2.0</mass>
        <inertia>
          <ixx>0.11041666666666668</ixx>
          <ixy>0.0</ixy>
          <ixz>0.0</ixx>
          <iyy>0.11333333333333336</iyy>
          <iyz>0.0</iyz>
          <izz>0.010416666666666666</izz>
        </inertia>
      </inertial>
    </link>
    <joint name="wheel_front_right_joint" type="continuous">
      <parent>wheel_module_front_right</parent>
      <child>wheel_front_right</child>
      <pose>0 -0.1 -0.4 1.5707963267948966 0 0</pose>
      <axis>
        <xyz>0 0 1</xyz>
      </axis>
    </joint>
    <link name="wheel_front_right">
      <visual name="wheel_front_right_visual">
        <geometry>
          <cylinder>
            <radius>0.3</radius>
            <length>0.1</length>
          </cylinder>
        </geometry>
        <material>grey</material>
      </visual>
      <collision name="wheel_front_right_collision">
        <geometry>
          <cylinder>
            <radius>0.3</radius>
            <length>0.1</length>
          </cylinder>
        </geometry>
        <surface>
          <!-- This friction pamareter don't contain reliable data!! -->
          <friction>
            <ode>
              <mu>100000.0</mu>
              <mu2>100000.0</mu2>
              <fdir1>0 0 0</fdir1>
              <slip1>0.0</slip1>
              <slip2>0.0</slip2>
            </ode>
          </friction>
          <contact>
            <ode>
              <soft_cfm>0</soft_cfm>
              <soft_erp>0.2</soft_erp>
              <kp>1e+5</kp>
              <kd>1</kd>
              <max_vel>0.01</max_vel>
              <min_depth>0.001</min_depth>
            </ode>
          </contact>
        </surface>
      </collision>
      <inertial>
        <pose>0 0 0 0 0 0</pose>
        <mass>1.0</mass>
        <inertia>
          <ixx>0.02333333333333333</ixx>
          <ixy>0.0</ixy>
          <ixz>0.0</ixx>
          <iyy>0.02333333333333333</iyy>
          <iyz>0.0</iyz>
          <izz>0.045</izz>
        </inertia>
      </inertial>
    </link>

    <joint name="wheel_module_rear_left_joint" type="fixed">
      <parent>rear_left</parent>
      <child>wheel_module_rear_left</child>
      <pose>0 0 -0.4 0 0 0</pose>
    </joint>
    <link name="wheel_module_rear_left">
      <visual name="wheel_module_rear_left_visual">
        <pose>0 0 0 0 0 0</pose>
        <geometry>
          <box>
            <size>0.2 0.15 0.8</size>
          </box>
        </geometry>
        <material>grey</material>
      </visual>
      <collision name="wheel_module_rear_left_collision">
        <pose>0 0 0 0 0 0</pose>
        <geometry>
          <box>
            <size>0.2 0.15 0.8</size>
          </box>
        </geometry>
      </collision>
      <inertial>
        <pose>0 0 0 0 0 0</pose>
        <mass>2.0</mass>
        <inertia>
          <ixx>0.11041666666666668</ixx>
          <ixy>0.0</ixy>
          <ixz>0.0</ixx>
          <iyy>0.11333333333333336</iyy>
          <iyz>0.0</iyz>
          <izz>0.010416666666666666</izz>
        </inertia>
      </inertial>
    </link>
    <joint name="wheel_rear_left_joint" type="continuous">
      <parent>wheel_module_rear_left</parent>
      <child>wheel_rear_left</child>
      <pose>0 0.1 -0.4 -1.5707963267948966 0 0</pose>
      <axis>
        <xyz>0 0 1</xyz>
      </axis>
    </joint>
    <link name="wheel_rear_left">
      <visual name="wheel_rear_left_visual">
        <geometry>
          <cylinder>
            <radius>0.3</radius>
            <length>0.1</length>
          </cylinder>
        </geometry>
        <material>grey</material>
      </visual>
      <collision name="wheel_rear_left_collision">
        <geometry>
          <cylinder>
            <radius>0.3</radius>
            <length>0.1</length>
          </cylinder>
        </geometry>
        <surface>
          <!-- This friction pamareter don't contain reliable data!! -->
          <friction>
            <ode>
              <mu>100000.0</mu>
              <mu2>100000.0</mu2>
              <fdir1>0 0 0</fdir1>
              <slip1>0.0</slip1>
              <slip2>0.0</slip2>
            </ode>
          </friction>
          <contact>
            <ode>
              <soft_cfm>0</soft_cfm>
              <soft_erp>0.2</soft_erp>
              <kp>1e+5</kp>
              <kd>1</kd>
              <max_vel>0.01</max_vel>
              <min_depth>0.001</min_depth>
            </ode>
          </contact>
        </surface>
      </collision>
      <inertial>
        <pose>0 0 0 0 0 0</pose>
        <mass>1.0</mass>
        <inertia>
          <ixx>0.02333333333333333</ixx>
          <ixy>0.0</ixy>
          <ixz>0.0</ixx>
          <iyy>0.02333333333333333</iyy>
          <iyz>0.0</iyz>
          <izz>0.045</izz>
        </inertia>
      </inertial>
    </link>

    <joint name="wheel_module_rear_right_joint" type="fixed">
      <parent>rear_right</parent>
      <child>wheel_module_rear_right</child>
      <pose>0 0 -0.4 0 0 0</pose>
    </joint>
    <link name="wheel_module_rear_right">
      <visual name="wheel_module_rear_right_visual">
        <pose>0 0 0 0 0 0</pose>
        <geometry>
          <box>
            <size>0.2 0.15 0.8</size>
          </box>
        </geometry>
        <material>grey</material>
      </visual>
      <collision name="wheel_module_rear_right_collision">
        <pose>0 0 0 0 0 0</pose>
        <geometry>
          <box>
            <size>0.2 0.15 0.8</size>
          </box>
        </geometry>
      </collision>
      <inertial>
        <pose>0 0 0 0 0 0</pose>
        <mass>2.0</mass>
        <inertia>
          <ixx>0.11041666666666668</ixx>
          <ixy>0.0</ixy>
          <ixz>0.0</ixx>
          <iyy>0.11333333333333336</iyy>
          <iyz>0.0</iyz>
          <izz>0.010416666666666666</izz>
        </inertia>
      </inertial>
    </link>
    <joint name="wheel_rear_right_joint" type="continuous">
      <parent>wheel_module_rear_right</parent>
      <child>wheel_rear_right</child>
      <pose>0 -0.1 -0.4 1.5707963267948966 0 0</pose>
      <axis>
        <xyz>0 0 1</xyz>
      </axis>
    </joint>
    <link name="wheel_rear_right">
      <visual name="wheel_rear_right_visual">
        <geometry>
          <cylinder>
            <radius>0.3</radius>
            <length>0.1</length>
          </cylinder>
        </geometry>
        <material>grey</material>
      </visual>
      <collision name="wheel_rear_right_collision">
        <geometry>
          <cylinder>
            <radius>0.3</radius>
            <length>0.1</length>
          </cylinder>
        </geometry>
        <surface>
          <!-- This friction pamareter don't contain reliable data!! -->
          <friction>
            <ode>
              <mu>100000.0</mu>
              <mu2>100000.0</mu2>
              <fdir1>0 0 0</fdir1>
              <slip1>0.0</slip1>
              <slip2>0.0</slip2>
            </ode>
          </friction>
          <contact>
            <ode>
              <soft_cfm>0</soft_cfm>
              <soft_erp>0.2</soft_erp>
              <kp>1e+5</kp>
              <kd>1</kd>
              <max_vel>0.01</max_vel>
              <min_depth>0.001</min_depth>
            </ode>
          </contact>
        </surface>
      </collision>
      <inertial>
        <pose>0 0 0 0 0 0</pose>
        <mass>1.0</mass>
        <inertia>
          <ixx>0.02333333333333333</ixx>
          <ixy>0.0</ixy>
          <ixz>0.0</ixx>
          <iyy>0.02333333333333333</iyy>
          <iyz>0.0</iyz>
          <izz>0.045</izz>
        </inertia>
      </inertial>
    </link>

    <!-- IMU -->
    <joint name="imu_joint" type="fixed">
      <parent>base_link</parent>
      <child>imu_link</child>
      <pose>0.0 0.0 0.09999999999999999 0 0 0</pose>
    </joint>
    <link name="imu_link">
      <sensor name="imu_sensor" type="imu">
        <always_on>true</always_on>
        <update_rate>200</update_rate>
        <imu>
          <angular_velocity>
            <x>
              <noise type="gaussian">
                <mean>0.0</mean>
                <stddev>2e-4</stddev>
              </noise>
            </x>
            <y>
              <noise type="gaussian">
                <mean>0.0</mean>
                <stddev>2e-4</stddev>
              </noise>
            </y>
            <z>
              <noise type="gaussian">
                <mean>0.0</mean>
                <stddev>2e-4</stddev>
              </noise>
            </z>
          </angular_velocity>
          <linear_acceleration>
            <x>
              <noise type="gaussian">
                <mean>0.0</mean>
                <stddev>1.7e-2</stddev>
              </noise>
            </x>
            <y>
              <noise type="gaussian">
                <mean>0.0</mean>
                <stddev>1.7e-2</stddev>
              </noise>
            </y>
            <z>
              <noise type="gaussian">
                <mean>0.0</mean>
                <stddev>1.7e-2</stddev>
              </noise>
            </z>
          </linear_acceleration>
        </imu>
        <plugin name="imu_plugin" filename="libgazebo_ros_imu_sensor.so">
          <ros>
            <remapping>~/out:=imu</remapping>
          </ros>
        </plugin>
      </sensor>
    </link>

    <!-- GPS -->
    <joint name="gps_joint" type="fixed">
      <parent>base_link</parent>
      <child>gps_link</child>
      <pose>0 0 0 0 0 0</pose>
    </joint>
    <link name="gps_link">
      <inertial>
        <pose>0 0 0 0 0 0</pose>
        <mass>0.125</mass>
        <inertia>
          <ixx>0.001</ixx>
          <ixy>0.0</ixy>
          <ixz>0.0</ixx>
          <iyy>0.001</iyy>
          <iyz>0.0</iyz>
          <izz>0.001</izz>
        </inertia>
      </inertial>
      <sensor name="gps_sensor" type="gps">
        <always_on>true</always_on>
        <update_rate>1</update_rate>
        <pose>0 0 0 0 0 0</pose>
        <gps>
          <position_sensing>
            <horizontal>
              <noise type="gaussian">
                <mean>0.0</mean>
                <stddev>0.01</stddev>
              </noise>
            </horizontal>
            <vertical>
              <noise type="gaussian">
                <mean>0.0</mean>
                <stddev>0.01</stddev>
              </noise>
            </vertical>
          </position_sensing>
        </gps>
        <plugin name="gps_plugin" filename="libgazebo_ros_gps_sensor.so">
          <ros>
            <remapping>~/out:=/gps/fix</remapping>
          </ros>
        </plugin>
      </sensor>
    </link>

    <!-- 2D Lidar -->
    <joint name="scan_joint" type="fixed">
      <parent>base_link</parent>
      <child>base_scan</child>
      <pose>1.5 0 -0.2 0 0 0</pose>
    </joint>
    <link name="base_scan">
      <visual name="base_scan_visual">
        <pose>0 0 0 0 0 0</pose>
        <geometry>
          <mesh>
            <uri>package://turtlebot3_gazebo/models/turtlebot3_common/meshes/lds.dae</uri>
            <scale>0.001 0.001 0.001</scale>
          </mesh>
        </geometry>
        <material>dark</material>
      </visual>
      <collision name="base_scan_collision">
        <pose>0.015 0 -0.0065 0 0 0</pose>
        <geometry>
          <cylinder>
            <radius>0.055</radius>
            <length>0.0315</length>
          </cylinder>
        </geometry>
      </collision>
      <inertial>
        <pose>0 0 0 0 0 0</pose>
        <mass>0.125</mass>
        <inertia>
          <ixx>0.001</ixx>
          <ixy>0.0</ixy>
          <ixz>0.0</ixx>
          <iyy>0.001</iyy>
          <iyz>0.0</iyz>
          <izz>0.001</izz>
        </inertia>
      </inertial>
      <sensor name="lidar_sensor" type="ray">
        <always_on>true</always_on>
        <update_rate>5</update_rate>
        <pose>0 0 0 0 0 0</pose>
        <ray>
          <scan>
            <horizontal>
              <samples>360</samples>
              <resolution>1.0</resolution>
              <min_angle>0.0</min_angle>
              <max_angle>6.28</max_angle>
            </horizontal>
          </scan>
          <range>
            <min>0.0</min>
            <max>20.0</max>
            <resolution>0.015</resolution>
          </range>
          <noise>
            <type>gaussian</type>
            <mean>0.0</mean>
            <stddev>0.01</stddev>
          </noise>
        </ray>
        <plugin name="lidar_plugin" filename="libgazebo_ros_ray_sensor.so">
          <ros>
            <remapping>~/out:=scan</remapping>
          </ros>
          <output_type>sensor_msgs/LaserScan</output_type>
          <frame_name>base_scan</frame_name>
        </plugin>
      </sensor>
    </link>

    <!-- Diff Drive Plugin -->
    <plugin name="turtlebot3_diff_drive" filename="libgazebo_ros_diff_drive.so">
      <ros>
        <!--since gazebo_plugins publish tf topic in global namespace /tf only and it
            cannot be remapped like (namespace/tf) through launch arguments -->
        <remapping>/tf:=tf</remapping>
      </ros>

      <update_rate>30</update_rate>

      <!-- wheels -->
      <left_joint>wheel_front_left_joint</left_joint>
      <right_joint>wheel_front_right_joint</right_joint>
      <left_joint>wheel_rear_left_joint</left_joint>
      <right_joint>wheel_rear_right_joint</right_joint>
      <!-- !HARDCODED -->
      <wheel_separation>1.2</wheel_separation>
      <wheel_diameter>0.3</wheel_diameter>
      <max_wheel_torque>200</max_wheel_torque>
      <max_wheel_acceleration>1.0</max_wheel_acceleration>
      <command_topic>cmd_vel</command_topic>
      <publish_odom>true</publish_odom>
      <publish_odom_tf>false</publish_odom_tf>
      <publish_wheel_tf>false</publish_wheel_tf>
      <odometry_topic>odom</odometry_topic>
      <odometry_frame>odom</odometry_frame>
      <robot_base_frame>base_footprint</robot_base_frame>
    </plugin>

    <plugin name="turtlebot3_joint_state" filename="libgazebo_ros_joint_state_publisher.so">
      <ros>
        <remapping>~/out:=joint_states</remapping>
      </ros>
      <update_rate>30</update_rate>
      <joint_name>wheel_front_left_joint</joint_name>
      <joint_name>wheel_front_right_joint</joint_name>
      <joint_name>wheel_rear_left_joint</joint_name>
      <joint_name>wheel_rear_right_joint</joint_name>
    </plugin>

  </model>
</sdf>
```